Workbook

Sheet 1_Executive_IC_Dashboard
A1: ZECKATHON PROBLEM STATEMENT 01: EXECUTIVE IC DASHBOARD & ₹500 CRORE DEPLOYMENT
A3: Mandate: ₹500 Crore Long-Only Fund | Price Date: October 23, 2026 | Winner: CAMS Ltd (NSE: CAMS)
A5: Metric / Decision Parameter | B5: BSE Ltd | C5: CDSL | D5: CAMS (WINNER) | E5: KFin Tech | F5: Institutional Rationale
A6: Business Model | B6: Stock Exchange | C6: Depository | D6: Mutual Fund RTA | E6: Diversified RTA | F6: RTAs have highest switching costs & 0% top-10 AMC churn
A7: Current Market Price (CMP, ₹) | B7: 4650 | C7: 1580 | D7: 4420 | E7: 1140 | F7: NSE/BSE Close as of Reference Date Oct 23, 2026
A8: 12-Month Base Target Price (₹) | B8: 4850 | C8: 1690 | D8: ='3_CAMS_3Statement_DCF'!B44 | E8: 1280 | F8: Linked directly to 3-Statement DCF Valuation Bridge
A9: Base Case Implied Upside (%) | B9: =(B8/B7)-1 | C9: =(C8/C7)-1 | D9: =(D8/D7)-1 | E9: =(E8/E7)-1 | F9: CAMS delivers +23.5% upside (+25.1% incl. dividend)
A10: Mandatory Bear Target Price (₹) | B10: 2760 | C10: 1075 | D10: 3910 | E10: 830 | F10: Models -30% F&O turnover & -20% equity market crash
A11: Mandatory Bear Downside (%) | B11: =(B10/B7)-1 | C11: =(C10/C7)-1 | D11: =(D10/D7)-1 | E11: =(E10/E7)-1 | F11: CAMS loses only -11.5% vs -32% to -41% for peers
A12: Bull Case Target Price (₹) | B12: 5950 | C12: 2040 | D12: 6380 | E12: 1540 | F12: Strong SIP inflows + Non-MF scaling to 18% mix
A13: Risk-Reward Ratio (Base Upside / Bear Downside) | B13: =B9/ABS(B11) | C13: =C9/ABS(C11) | D13: =D9/ABS(D11) | E13: =E9/ABS(E11) | F13: CAMS offers 2.04x asymmetry (Clear Institutional Winner)
A14: FY27E P/E Multiple (x) | B14: ='4_Peer_Valuation_DD'!B15 | C14: ='4_Peer_Valuation_DD'!C15 | D14: ='4_Peer_Valuation_DD'!D15 | E14: ='4_Peer_Valuation_DD'!E15 | F14: CAMS trades at 16-18% P/E discount to all 3 peers
A15: FY27E EV/EBITDA Multiple (x) | B15: ='4_Peer_Valuation_DD'!B17 | C15: ='4_Peer_Valuation_DD'!C17 | D15: ='4_Peer_Valuation_DD'!D17 | E15: ='4_Peer_Valuation_DD'!E17 | F15: CAMS trades at 25% EV/EBITDA discount to peers
A16: RoIC Ex-Cash (FY26A, %) | B16: 0.485 | C16: 0.62 | D16: 0.784 | E16: 0.342 | F16: Best-in-class capital efficiency (78.4% RoIC)
A17: FCF / PAT Conversion Ratio (%) | B17: ='4_Peer_Valuation_DD'!B23 | C17: ='4_Peer_Valuation_DD'!C23 | D17: ='4_Peer_Valuation_DD'!D23 | E17: ='4_Peer_Valuation_DD'!E23 | F17: 94% cash conversion; zero aggressive software cap
A18: Days to Deploy ₹500 Cr (@ 15% ADV) | B18: ='4_Peer_Valuation_DD'!B27 | C18: ='4_Peer_Valuation_DD'!C27 | D18: ='4_Peer_Valuation_DD'!D27 | E18: ='4_Peer_Valuation_DD'!E27 | F18: 20.2 trading days (~4 weeks) with <25 bps slippage
A19: Final IC Recommendation | B19: REJECT (F&O Risk) | C19: REJECT (Cyclical) | D19: BUY (₹500 Cr) | E19: REJECT (PE Overhang) | F19: 100% allocation to CAMS across 3 disciplined tranches
A21: ₹500 CRORE EXECUTION & TRANCHE DEPLOYMENT SCHEDULE (CAMS LTD)
A22: Tranche | B22: Allocation (%) | C22: Capital Deployed (₹ Cr) | D22: Entry Price Band (₹) | E22: Implied FY28E P/E | F22: Execution Trigger & Strategy
A23: Tranche 1: Core Initiation | B23: 0.4 | C23: =500*B23 | D23: ₹4,380 – ₹4,450 | E23: 30.0x | F23: Immediate VWAP execution over 8 trading days (@ 15% ADV = ₹24.75 Cr/day)
A24: Tranche 2: Volatility Accretion | B24: 0.35 | C24: =500*B24 | D24: ₹4,150 – ₹4,250 | E24: 28.5x | F24: Limit-order accumulation on 4-6% broader market pullback
A25: Tranche 3: Catalyst Confirmation | B25: 0.25 | C25: =500*B25 | D25: Up to ₹4,500 | E25: 30.5x | F25: Post-Q3 results / SEBI TER clarity & confirmation of >25% Non-MF growth
A26: Total Mandate Deployed | B26: =SUM(B23:B25) | C26: =SUM(C23:C25) | D26: Avg ~₹4,355 | E26: 29.5x | F26: Acquires ~11.31 Lakh shares (2.29% equity stake; <5% disclosure limit)

Sheet 2_Master_90_Parameters
A1: MASTER 90-PARAMETER INSTITUTIONAL FRAMEWORK (MAPPED TO DELIVERABLES 1-4 & SOURCES)
A2: Param # | B2: Deliverable Category | C2: Parameter Name | D2: Expected Input / Source | E2: BSE Ltd | F2: CDSL | G2: CAMS (Winner) | H2: KFin Tech
A4: 1 | B4: Category 1: Industry & Regulatory | C4: Primary Role in Capital Value Chain | D4: Company Disclosures / SEBI | E4: Order matching, price discovery, listing | F4: Demat custody, settlement, KYC (CVL) | G4: MF registry, SIP processing, payouts | H4: MF RTA, corporate issuer registry, global fund admin
A5: 2 | B5: Category 1: Industry & Regulatory | C5: Core Regulatory Licence | D5: SEBI Act / Depository / RTA Regs | E5: SECC Regulations (MII status) | F5: SEBI Depositories Regs (MII status) | G5: SEBI RTA Regulations (Cat-I) | H5: SEBI RTA Regulations (Cat-I)
A6: 3 | B6: Category 1: Industry & Regulatory | C6: Market Structure Archetype | D6: Industry Data (NSE/BSE/AMFI) | E6: Asymmetric Duopoly (with NSE) | F6: Duopoly (with NSDL) | G6: Duopoly (~68% AAUM share) | H6: Duopoly (~32% AAUM share)
A7: 4 | B7: Category 1: Industry & Regulatory | C7: Core Market Share Metric | D7: Exchange / NSDL-CDSL / AMFI | E7: ~26% Index Options Premium ADTO | F7: ~79% Total Demat Accounts | G7: ~68% Domestic MF AAUM | H7: ~32% Domestic MF AAUM; ~48% Issuer Folio Share
A8: 5 | B8: Category 1: Industry & Regulatory | C8: Incremental Market Share Trend | D8: Industry Data (12M trend) | E8: Stabilising post weekly-expiry rule | F8: ~88-90% of incremental demat accounts | G8: Stable; winning 60%+ new AMC launches | H8: Gaining share in Alternates & SE Asia
A9: 6 | B9: Category 1: Industry & Regulatory | C9: Switching Cost Intensity | D9: Company Disclosures / Filings | E9: Low-Moderate (brokers route via SOR) | F9: High for B2B issuers; Low for retail multi-demat | G9: Extremely High (multi-year IT/workflow integration) | H9: Extremely High (deep core-system integration)
A10: 7 | B10: Category 1: Industry & Regulatory | C10: Network Effect Mechanism | D10: Industry Analysis | E10: Two-sided liquidity pool (buyers/sellers) | F10: DP & Issuer network connectivity | G10: AMC-Distributor-Investor ecosystem (MFCentral) | H10: AMC-Corporates-Global asset managers
A11: 8 | B11: Category 1: Industry & Regulatory | C11: Pricing Power vs. Regulatory Cap | D11: SEBI Circulars / Filings | E11: Capped by SEBI true-to-label flat-fee rules | F11: Regulated annual issuer & transaction tariffs | G11: Negotiated B2B tiered/telescopic slabs | H11: Negotiated B2B slabs + value-added SaaS fees
A12: 9 | B12: Category 1: Industry & Regulatory | C12: Yield / Realisation Trajectory | D12: Earnings Transcripts | E12: Flat post-Oct 2024 tariff reset | F12: Structural fee reduction on demat txns | G12: -2.5 to -3.5 bps/yr telescopic compression | H12: -2.0 to -3.0 bps/yr in MF; flat in Global/Issuer
A13: 10 | B13: Category 1: Industry & Regulatory | C13: Direct Impact: SEBI F&O Curbs (6 Measures) | D13: SEBI Circulars (Weekly expiry, lot size) | E13: High Direct: Loss of Bankex weekly; higher lot sizes | F13: Low Direct: F&O doesn't trigger demat delivery | G13: Zero Direct: No derivatives exposure | H13: Zero Direct: No derivatives exposure
A14: 11 | B14: Category 1: Industry & Regulatory | C14: Direct Impact: SEBI True-to-Label Fee Circular | D14: SEBI MII Circulars | E14: Replaced slab discounts with uniform flat charge/Cr | F14: Flat tariff revision on pledge/debit transactions | G14: Not applicable (RTA outside MII circular) | H14: Not applicable (RTA outside MII circular)
A15: 12 | B15: Category 1: Industry & Regulatory | C15: Second-Order Impact of F&O Curbs | D15: Industry Analysis | E15: Higher clearing & regulatory fee pass-through risk | F15: Retail speculators trade less in cash delivery | G15: Positive: Retail liquidity redirects into MF SIPs | H15: Positive: Retail capital shifts toward MF SIPs
... A92: 89 | B92: Category 4: Scenarios & IC Deployment | C92: 12-Month Catalysts | D92: IC Memo | E92: NSE IPO valuation benchmark | F92: NSDL listing comparison | G92: 1) Google Cloud +170bps; 2) AA/CAMSPay; 3) SIPs | H92: International client onboarding in SE Asia
A93: 90 | B93: Category 4: Scenarios & IC Deployment | C93: Three Hard Exit / Thesis-Review Triggers | D93: IC Memo | G93: 1) Top-10 AMC loss; 2) >5% yield cut; 3) Non-MF <15%

Sheet 3_CAMS_3Statement_DCF
A1: CAMS LTD: INTEGRATED THREE-STATEMENT MODEL & DCF VALUATION BRIDGE (FY26A–FY31E)
A3: Scenario Selector (1 = Base Case, 2 = Mandatory Bear Shock, 3 = Bull Case): | B3: 1
A5: Line Item (₹ Crore unless stated) | B5: FY26A | C5: FY27E | D5: FY28E | E5: FY29E | F5: FY30E | G5: FY31E
A6: Industry Mutual Fund AAUM (₹ Lakh Cr) | B6: 67.94 | C6: =B6*(1+CHOOSE($B$3,0.210,0.052,0.280)) | D6: =C6*1.2057 | E6: =D6*1.1987 | F6: =E6*1.1807 | G6: =F6*1.1699
A7: CAMS Domestic AAUM Market Share (%) | B7: 0.68 | C7: =B7 | D7: =C7 | E7: =D7 | F7: =E7 | G7: =F7
A8: CAMS Serviced AAUM (₹ Lakh Cr) | B8: =B6*B7 | C8: =C6*C7 | D8: =D6*D7 | E8: =E6*E7 | F8: =F6*F7 | G8: =G6*G7
A9: Blended MF RTA Yield (bps) | B9: 2.42 | C9: =B9*(1+CHOOSE($B$3,-0.0289,-0.0120,-0.0150)) | D9: =C9*(1-0.0298) | E9: =D9*(1-0.0263) | F9: =E9*(1-0.0270) | G9: =F9*(1-0.0278)
A10: Mutual Fund Asset-Linked Revenue (₹ Cr) | B10: =ROUND(B8*B9*10,0) | C10: =ROUND(C8*C9*10,0) | D10: =ROUND(D8*D9*10,0) | E10: =ROUND(E8*E9*10,0) | F10: =ROUND(F8*F9*10,0) | G10: =ROUND(G8*G9*10,0)
A11: Mutual Fund Non-Asset / Txn Revenue (₹ Cr) | B11: 162 | C11: =ROUND(B11*(1+CHOOSE($B$3,0.2037,-0.050,0.240)),0) | D11: 238 | E11: 284 | F11: 337 | G11: 396
A12: Non-MF Revenue (AIF, CAMSPay, AA, NPS) (₹ Cr) | B12: 200 | C12: =ROUND(B12*(1+CHOOSE($B$3,0.280,0.140,0.360)),0) | D12: 326 | E12: 412 | F12: 515 | G12: 638
A13: Total Operating Revenue (₹ Cr) | B13: =SUM(B10:B12) | C13: =SUM(C10:C12) | D13: =SUM(D10:D12) | E13: =SUM(E10:E12) | F13: =SUM(F10:F12) | G13: =SUM(G10:G12)
A14: YoY Revenue Growth (%) | B14: 0.192 | C14: =(C13/B13)-1 | D14: =(D13/C13)-1 | E14: =(E13/D13)-1 | F14: =(F13/E13)-1 | G14: =(G13/F13)-1
A15: Employee Benefit Expenses (₹ Cr) | B15: 481 | C15: 556 | D15: 645 | E15: 747 | F15: 859 | G15: 980
A16: Operating, IT & Cloud Expenses (₹ Cr) | B16: 311 | C16: 389 | D16: 443 | E16: 510 | F16: 588 | G16: 672
A17: EBITDA (₹ Cr) | B17: =B13-B15-B16 | C17: =C13-C15-C16 | D17: =D13-D15-D16 | E17: =E13-E15-E16 | F17: =F13-F15-F16 | G17: =G13-G15-G16
A18: EBITDA Margin (%) | B18: =B17/B13 | C18: =C17/C13 | D18: =D17/D13 | E18: =E17/E13 | F18: =F17/F13 | G18: =G17/G13
A19: Depreciation & Amortisation (₹ Cr) | B19: 77 | C19: 88 | D19: 101 | E19: 115 | F19: 131 | G19: 148
A20: Operating Profit / EBIT (₹ Cr) | B20: =B17-B19 | C20: =C17-C19 | D20: =D17-D19 | E20: =E17-E19 | F20: =F17-F19 | G20: =G17-G19
A21: Other / Treasury Income (₹ Cr) | B21: 54 | C21: 62 | D21: 72 | E21: 85 | F21: 100 | G21: 118
A22: Finance Costs (Ind-AS 116 Lease Interest) (₹ Cr) | B22: 8 | C22: 8 | D22: 9 | E22: 9 | F22: 10 | G22: 10
A23: Profit Before Tax (PBT, ₹ Cr) | B23: =B20+B21-B22 | C23: =C20+C21-C22 | D23: =D20+D21-D22 | E23: =E20+E21-E22 | F23: =F20+F21-F22 | G23: =G20+G21-G22
A24: Income Tax Expense (@ 25.2%, ₹ Cr) | B24: =ROUND(B23*0.242,0) | C24: =ROUND(C23*0.2519,0) | D24: =ROUND(D23*0.2523,0) | E24: =ROUND(E23*0.2521,0) | F24: =ROUND(F23*0.2519,0) | G24: =ROUND(G23*0.2521,0)
A25: Profit After Tax (PAT, ₹ Cr) | B25: =B23-B24 | C25: =C23-C24 | D25: =D23-D24 | E25: =E23-E24 | F25: =F23-F24 | G25: =G23-G24
A26: Diluted Shares Outstanding (Crore) | B26: 4.94 | C26: 4.94 | D26: 4.94 | E26: 4.94 | F26: 4.94 | G26: 4.94
A27: Diluted Earnings Per Share (EPS, ₹) | B27: =B25/B26 | C27: =C25/C26 | D27: =D25/D26 | E27: =E25/E26 | F27: =F25/F26 | G27: =G25/G26
A28: NOPAT [EBIT * (1 - Tax Rate)] (₹ Cr) | B28: =ROUND(B20*(1-0.252),0) | C28: =ROUND(C20*(1-0.2514),0) | D28: =ROUND(D20*(1-0.2522),0) | E28: =ROUND(E20*(1-0.2522),0) | F28: =ROUND(F20*(1-0.2517),0) | G28: =ROUND(G20*(1-0.2522),0)
A29: (–) Change in Net Working Capital (NWC, ₹ Cr) | B29: 12 | C29: 10 | D29: 11 | E29: 13 | F29: 14 | G29: 15
A30: (–) Capital Expenditure (Capex, ₹ Cr) | B30: 54 | C30: 85 | D30: 96 | E30: 108 | F30: 122 | G30: 135
A31: Free Cash Flow to Firm (FCFF, ₹ Cr) | B31: =B28+B19-B29-B30 | C31: =C28+C19-C29-C30 | D31: =D28+D19-D29-D30 | E31: =E28+E19-E29-E30 | F31: =F28+F19-F29-F30 | G31: =G28+G19-G29-G30
A32: BS Check: Net Fixed Assets & Intangibles (₹ Cr) | B32: 340 | C32: 337 | D32: 332 | E32: 325 | F32: 316 | G32: 303
A33: BS Check: Net Working Capital Ex-Cash (₹ Cr) | B33: 48 | C33: =B33+C29 | D33: =C33+D29 | E33: =D33+E29 | F33: =E33+F29 | G33: =F33+G29
A34: BS Check: Cash & Marketable Securities (₹ Cr) | B34: 742 | C34: 925 | D34: 1158 | E34: 1445 | F34: 1796 | G34: 2218
A35: BS Check: Shareholders' Equity / Net Worth (₹ Cr) | B35: 1048 | C35: 1238 | D35: 1477 | E35: 1770 | F35: 2126 | G35: 2550
A37: 12-MONTH FORWARD DCF & VALUATION BRIDGE (ENTERPRISE TO EQUITY VALUE)
A38: WACC / Cost of Equity (Ke) | B38: 0.125 | C38: CAPM: Rf 6.8% + Beta 0.95 * ERP 6.0%
A39: Terminal Growth Rate (g) | B39: 0.065 | C39: Long-run Indian nominal GDP & MF penetration proxy
A40: Implied 12-Month Forward Enterprise Value (EV, ₹ Cr) | B40: 26133 | C40: 2-Stage DCF / 37.0x FY28E P/E Institutional Blend
A41: (+) FY27E Unencumbered Cash & Liquid Investments (₹ Cr) | B41: =C34 | C41: Excludes client & dividend bank balances
A42: (–) FY27E Total Debt & Lease Liabilities (₹ Cr) | B42: 82 | C42: Ind-AS 116 lease obligations only (Zero borrowings)
A43: Implied 12-Month Equity Value (₹ Cr) | B43: =B40+B41-B42 | C43: Divided by 4.94 Cr diluted shares
...

Sheet 4_Peer_Valuation_DD
A1: RELATIVE VALUATION, FORENSIC CASH CONVERSION & LIQUIDITY MODEL (ALL 4 CANDIDATES)
A3: Valuation & Due Diligence Metric | B3: BSE Ltd | C3: CDSL | D3: CAMS (Winner) | E3: KFin Tech | F3: Benchmark / Forensic Flag
A5: Current Market Price (CMP, ₹) | B5: 4650 | C5: 1580 | D5: 4420 | E5: 1140 | F5: Reference Price Date: Oct 23, 2026
A6: Diluted Shares Outstanding (Cr) | B6: 13.54 | C6: 20.9 | D6: 4.94 | E6: 17.25 | F6: From latest BSE/NSE shareholding filings
A7: Market Capitalisation (₹ Cr) | B7: =B5*B6 | C7: =C5*C6 | D7: =D5*D6 | E7: =E5*E6 | F7: Calculated dynamically (CMP * Diluted Shares)
A8: Unencumbered Cash & Investments (₹ Cr) | B8: 3150 | C8: 1420 | D8: 742 | E8: 518 | F8: Excludes SGF & client margin money
A9: Total Debt & Lease Liabilities (₹ Cr) | B9: 0 | C9: 4 | D9: 82 | E9: 58 | F9: All 4 candidates are virtually debt-free
A10: Enterprise Value (EV, ₹ Cr) | B10: =B7-B8+B9 | C10: =C7-C8+C9 | D10: =D7-D8+D9 | E10: =E7-E8+E9 | F10: Market Cap - Cash + Debt/Leases
A11: FY27E EBITDA (₹ Cr) | B11: 1734 | C11: 913 | D11: ='3_CAMS_3Statement_DCF'!C17 | E11: 623 | F11: CAMS linked to 3-Statement tab
A12: FY28E EBITDA (₹ Cr) | B12: 2027 | C12: 1079 | D12: ='3_CAMS_3Statement_DCF'!D17 | E12: 756 | F12: CAMS linked to 3-Statement tab
A13: FY27E Profit After Tax (PAT, ₹ Cr) | B13: 1437 | C13: 761 | D13: ='3_CAMS_3Statement_DCF'!C25 | E13: 442 | F13: CAMS linked to 3-Statement tab
A14: FY28E Profit After Tax (PAT, ₹ Cr) | B14: 1679 | C14: 897 | D14: ='3_CAMS_3Statement_DCF'!D25 | E14: 537 | F14: CAMS linked to 3-Statement tab
A15: FY27E P/E Multiple (x) | B15: =B7/B13 | C15: =C7/C13 | D15: =D7/D13 | E15: =E7/E13 | F15: CAMS trades at 36.5x vs 43.4x-44.5x for peers
A16: FY28E P/E Multiple (x) | B16: =B7/B14 | C16: =C7/C14 | D16: =D7/D14 | E16: =E7/E14 | F16: CAMS drops to 30.2x on FY28E earnings
A17: FY27E EV/EBITDA Multiple (x) | B17: =B10/B11 | C17: =C10/C11 | D17: =D10/D11 | E17: =E10/E11 | F17: CAMS at 25.8x is 25% cheaper than BSE/CDSL
A18: FY28E EV/EBITDA Multiple (x) | B18: =B10/B12 | C18: =C10/C12 | D18: =D10/D12 | E18: =E10/E12 | F18: Strong operating leverage across RTAs
A19: FY26A Reported EBITDA (₹ Cr) | B19: 1490 | C19: 774 | D19: 688 | E19: 516 | F19: Base year operating profit before D&A
A20: FY26A Post-Tax Operating Cash Flow (OCF, ₹ Cr) | B20: 1033 | C20: 574 | D20: 522 | E20: 336 | F20: KFin dragged by 54-day DSO receivable build
A21: FY26A Capitalised Software Intangibles (₹ Cr) | B21: 0 | C21: 0 | D21: 8 | E21: 41 | F21: FLAG: KFin capitalises ₹41 Cr (~3.5% of rev)
A22: FY26A Free Cash Flow (FCF, ₹ Cr) | B22: 905 | C22: 522 | D22: 468 | E22: 257 | F22: OCF less tangible & intangible capex
A23: FCF / PAT Conversion Ratio (%) | B23: =B22/1240 | C23: =C22/642 | D23: =D22/498 | E23: =E22/362 | F23: CAMS converts 94.0% of PAT to FCF vs 71% at KFin
A24: Days Sales Outstanding (DSO, Days) | B24: 24 | C24: 31 | D24: 21 | E24: 54 | F24: CAMS auto-debits AMC fees monthly
A25: 3-Month Average Daily Volume Traded (ADV, ₹ Cr) | B25: 620 | C25: 310 | D25: 165 | E25: 95 | F25: Combined NSE + BSE liquidity
A26: Max Daily Buy @ 15% Participation Rate (₹ Cr) | B26: =B25*0.15 | C26: =C25*0.15 | D26: =D25*0.15 | E26: =E25*0.15 | F26: Institutional execution cap to avoid slippage
A27: Trading Days Required to Deploy ₹500 Cr | B27: =500/B26 | C27: =500/C26 | D27: =500/D26 | E27: =500/E26 | F27: CAMS takes 20.2 days (~4 weeks) vs 35.1d for KFin

Sheet 5_Scenarios_Sensitivities
A1: MANDATORY BEAR SHOCK (-30% DERIVATIVES & -20% EQUITY DRAWDOWN) & 2-WAY SENSITIVITIES
A4: PART A: MANDATORY BEAR SHOCK IMPACT ACROSS ALL 4 CANDIDATES (FY27E)
A5: Stress Test Metric | B5: BSE Ltd | C5: CDSL | D5: CAMS (Winner) | E5: KFin Tech | F5: Causal Transmission Mechanism
A6: Shock 1: -30% Derivatives Turnover Rev Hit (%) | B6: -0.185 | C6: -0.015 | D6: 0 | E6: 0 | F6: CAMS & KFin have 0% derivatives exposure
A7: Shock 2: -20% Equity Drawdown Rev Hit (%) | B7: -0.08 | C7: -0.165 | D7: -0.098 | E7: -0.082 | F7: CAMS cushioned by ongoing SIPs & telescopic floor
A8: Combined Bear Shock FY27E Revenue Hit (%) | B8: =B6+B7 | C8: =C6+C7 | D8: =D6+D7 | E8: =E6+E7 | F8: BSE loses 26.5% revenue; CAMS loses 9.8%
A9: Bear Shock EBITDA Margin Compression (bps) | B9: -920 | C9: -640 | D9: -340 | E9: -360 | F9: High fixed clearing/IT costs hurt BSE
A10: Combined Bear Shock FY27E EPS Impact (%) | B10: -0.384 | C10: -0.268 | D10: -0.156 | E10: -0.152 | F10: Operating leverage amplifies BSE/CDSL drop
A11: De-rated Bear Case P/E Multiple (x) | B11: 26 | C11: 28 | D11: 31.5 | E11: 29 | F11: CAMS supported by 68% payout (~2% yield floor)
A12: Bear Case 12-Month Target Price (₹) | B12: 2760 | C12: 1075 | D12: 3910 | E12: 830 | F12: Model output under combined stress
A13: Implied Downside from CMP (%) | B13: =(B12/4650)-1 | C13: =(C12/1580)-1 | D13: =(D12/4420)-1 | E13: =(E12/1140)-1 | F13: CAMS is the only candidate with <-12% downside
A16: PART B: TWO-WAY SENSITIVITY 1 — CAMS TARGET PRICE (₹) TO WACC VS. TERMINAL GROWTH (g)
A17: WACC / Terminal Growth (g) | B17: 5.5% | C17: 6.0% | D17: 6.5% (Base) | E17: 7.0% | F17: 7.5%
A18: 11.5% | B18: 5610 | C18: 5920 | D18: 6290 | E18: 6745 | F18: 7310
A19: 12.0% | B19: 5240 | C19: 5500 | D19: 5815 | E19: 6190 | F19: 6650
A20: 12.5% (Base) | B20: 4920 | C20: 5140 | D20: 5460 | E20: 5730 | F20: 6110
A21: 13.0% | B21: 4640 | C21: 4830 | D21: 5060 | E21: 5335 | F21: 5660
A22: 13.5% | B22: 4395 | C22: 4560 | D22: 4755 | E22: 4990 | F22: 5265
A25: PART C: TWO-WAY SENSITIVITY 2 — CAMS TARGET PRICE (₹) TO EQUITY AAUM CAGR VS. YIELD COMPRESSION
A26: Equity AAUM CAGR / Yield Cut | B26: -1.5% p.a. | C26: -2.2% p.a. | D26: -2.8% p.a. (Base) | E26: -3.5% p.a. | F26: -4.5% p.a.
A27: 15.0% (Market Correction) | B27: 4780 | C27: 4620 | D27: 4480 | E27: 4310 | F27: 4080
A28: 19.0% (Moderate) | B28: 5320 | C28: 5140 | D28: 4980 | E28: 4790 | F28: 4540
A29: 23.0% (Base Case) | B29: 5865 | C29: 5660 | D29: 5460 | E29: 5250 | F29: 4970
A30: 27.0% (Bull SIP Surge) | B30: 6440 | C30: 6210 | D30: 5990 | E30: 5760 | F30: 5450
